<robot name="onshape">

    <!-- <link name="world"/>

    <joint name="fixed" type="fixed">
        <parent link="world"/>
        <child link="bodyv2"/>
    </joint> -->

    <link name="bodyv2">
        <visual>
            <origin xyz="0 0 0" rpy="0 -0 0" />
            <geometry>
                <mesh filename="../meshes/bodyv2.obj" />
            </geometry>
            <material name="bodyv2_material">
                <color
                    rgba="0.647058 0.647058 0.647058 1.0" />
            </material>
        </visual>
        <!-- <collision>
            <origin rpy="0 0 0" xyz="0 0 0.0208"/>
            <geometry>
                <box size="0.154 0.224 0.0415"/>
            </geometry>
        </collision> -->
        <inertial>
            <origin
                xyz="-0.000161 0.002069 0.018635"
                rpy="0 0 0" />
            <mass value="1.203737" />
            <inertia ixx="0.010656" ixy="1.100903e-06"
                ixz="2.500707e-06" iyy="0.007165"
                iyz="2.610268e-05" izz="0.017431" />
        </inertial>
    </link>



    <link name="coxav2-cp_r">
        <visual>
            <origin xyz="0.044924 3.384141e-16 0.015349"
                rpy="-2.220446e-16 4.157296e-27 7.478872e-17" />
            <geometry>
                <mesh filename="../meshes/coxav2-cp_r.obj" />
            </geometry>
            <material name="coxav2-cp_r_material">
                <color rgba="0.231372 0.380392 0.705882 1.0" />
            </material>
        </visual>
        <collision>
            <origin xyz="0.0155 0.0 0.0246" rpy="0.0 0.0 0.0"/>
            <geometry>  
                <box size="0.096265 0.0415 0.073"/>
            </geometry>
        </collision>
        <inertial>
            <origin xyz="0.030948 0.001527 0.025335"
                rpy="0 0 0" />
            <mass value="0.128842" />
            <inertia ixx="0.000110" ixy="-2.814921e-06"
                ixz="8.925042e-06" iyy="0.000160"
                iyz="1.713514e-06" izz="9.272238e-05" />
        </inertial>
    </link>

    <link name="femurv2-cp_r">
        <visual>
            <origin xyz="0.118313 -1.387778e-17 0.025050"
                rpy="-1.570796 2.315452e-16 -1.879225e-32" />
            <geometry>
                <mesh filename="../meshes/femurv2-cp_r.obj" />
            </geometry>
            <material name="femurv2-cp_r_material">
                <color
                    rgba="0.972549 0.529411 0.003921 1.0" />
            </material>
        </visual>
        <!-- <collision>
            <origin xyz="0.059156 0.0 0.0246" rpy="0.0 0.0 0.0"/>
            <geometry>  
                <box size="0.156314 0.0415 0.073"/>
            </geometry>
        </collision> -->
        <inertial>
            <origin xyz="0.060825 -1.513620e-09 0.026970"
                rpy="0 0 0" />
            <mass value="0.120701" />
            <inertia ixx="0.000123" ixy="-3.224433e-06"
                ixz="5.137608e-07" iyy="0.000324"
                iyz="-2.118779e-13" izz="0.000236" />
        </inertial>
    </link>

    <link name="tibiav2-cp_r">
        <visual>
            <origin xyz="0.221170 0.000104 0.025250"
                rpy="-1.570796 2.088130e-16 -2.465190e-32" />
            <geometry>
                <mesh filename="../meshes/tibiav2-cp_r.obj" />
            </geometry>
            <material name="tibiav2-cp_r_material">
                <color
                    rgba="0.980392 0.713725 0.003921 1.0" />
            </material>
        </visual>
        <!-- <collision>
            <origin xyz="0.013524 0.003617 0.02509" rpy="0.0 0.0 0.261341 "/>
            <geometry>  
                <box size="0.0655 0.0415 0.0417"/>
            </geometry>
        </collision> -->
        <inertial>
            <origin xyz="0.082592 0.012229 0.024032"
                rpy="0 0 0" />
            <mass value="0.168609" />
            <inertia ixx="6.244932e-05" ixy="-5.806436e-05"
                ixz="-1.625147e-05" iyy="0.000862"
                iyz="-2.394794e-06" izz="0.000872" />
        </inertial>
    </link>

    <joint name="FemurTibia1" type="revolute">
        <origin xyz="0.118313 -1.908195e-17 -4.163336e-17"
            rpy="-1.695348e-17 7.492361e-17 5.551115e-17" />
        <parent link="femurv2-cp_r" />
        <child link="tibiav2-cp_r" />
        <axis xyz="0 0 1" />
        <limit effort="1" velocity="20" />
        <joint_properties friction="0.0" />
    </joint>

    <joint name="CoxaFemur1" type="revolute">
        <origin xyz="0.044924 0.025050 0.015349"
            rpy="1.570796 4.157297e-27 1.352558e-16" />
        <parent link="coxav2-cp_r" />
        <child link="femurv2-cp_r" />
        <axis xyz="0 0 1" />
        <limit effort="1" velocity="20" />
        <joint_properties friction="0.0" />
    </joint>

    <joint name="BodyCoxa1" type="revolute">
        <origin xyz="0.098035 0.150960 -0.004500"
            rpy="0 -2.465190e-32 0.994837" />
        <parent link="bodyv2" />
        <child link="coxav2-cp_r" />
        <axis xyz="0 0 1" />
        <limit effort="1" velocity="20" />
        <joint_properties friction="0.0" />
    </joint>

    <link name="coxav2-cp_r_2">
        <visual>
            <origin xyz="0.044924 3.202813e-16 0.015349"
                rpy="-2.220446e-16 4.157296e-27 7.918786e-59" />
            <geometry>
                <mesh filename="../meshes/coxav2-cp_r.obj" />
            </geometry>
            <material name="coxav2-cp_r_material">
                <color rgba="0.231372 0.380392 0.705882 1.0" />
            </material>
        </visual>
        <collision>
            <origin xyz="0.0155 0.0 0.0246" rpy="0.0 0.0 0.0"/>
            <geometry>  
                <box size="0.096265 0.0415 0.073"/>
            </geometry>
        </collision>
        <inertial>
            <origin xyz="0.030948 0.001527 0.025335"
                rpy="0 0 0" />
            <mass value="0.128842" />
            <inertia ixx="0.000110" ixy="-2.814921e-06"
                ixz="8.925042e-06" iyy="0.000160"
                iyz="1.713514e-06" izz="9.272238e-05" />
        </inertial>
    </link>

    <link name="femurv2-cp_r_2">
        <visual>
            <origin xyz="0.118313 -1.387778e-17 0.025049"
                rpy="-1.570796 2.872393e-16 0" />
            <geometry>
                <mesh filename="../meshes/femurv2-cp_r.obj" />
            </geometry>
            <material name="femurv2-cp_r_material">
                <color
                    rgba="0.972549 0.529411 0.003921 1.0" />
            </material>
        </visual>
        <!-- <collision>
            <origin xyz="0.059156 0.0 0.0246" rpy="0.0 0.0 0.0"/>
            <geometry>  
                <box size="0.156314 0.0415 0.073"/>
            </geometry>
        </collision> -->
        <inertial>
            <origin xyz="0.060825 -1.513620e-09 0.026970"
                rpy="0 0 0" />
            <mass value="0.120701" />
            <inertia ixx="0.000123" ixy="-3.224433e-06"
                ixz="5.137608e-07" iyy="0.000324"
                iyz="-2.118779e-13" izz="0.000236" />
        </inertial>
    </link>

    <link name="tibiav2-cp_r_2">
        <visual>
            <origin xyz="0.221170 0.000104 0.025250"
                rpy="-1.570796 2.324140e-16 0" />
            <geometry>
                <mesh filename="../meshes/tibiav2-cp_r.obj" />
            </geometry>
            <material name="tibiav2-cp_r_material">
                <color
                    rgba="0.980392 0.713725 0.003921 1.0" />
            </material>
        </visual>
        <!-- <collision>
            <origin xyz="0.013524 0.003617 0.02509" rpy="0.0 0.0 0.261341 "/>
            <geometry>  
                <box size="0.0655 0.0415 0.0417"/>
            </geometry>
        </collision> -->
        <inertial>
            <origin xyz="0.082592 0.012229 0.024032"
                rpy="0 0 0" />
            <mass value="0.168609" />
            <inertia ixx="6.244932e-05" ixy="-5.806436e-05"
                ixz="-1.625147e-05" iyy="0.000862"
                iyz="-2.394794e-06" izz="0.000872" />
        </inertial>
    </link>

    <joint name="FemurTibia2" type="revolute">
        <origin xyz="0.118313 0 0" rpy="0 5.891547e-52 0" />
        <parent link="femurv2-cp_r_2" />
        <child link="tibiav2-cp_r_2" />
        <axis xyz="0 0 1" />
        <limit effort="1" velocity="20" />
        <joint_properties friction="0.0" />
    </joint>

    <joint name="CoxaFemur2" type="revolute">
        <origin xyz="0.044924 0.025050 0.015349"
            rpy="1.570796 4.157296e-27 1.183291e-30" />
        <parent link="coxav2-cp_r_2" />
        <child link="femurv2-cp_r_2" />
        <axis xyz="0 0 1" />
        <limit effort="1" velocity="20" />
        <joint_properties friction="0.0" />
    </joint>

    <joint name="BodyCoxa2" type="revolute">
        <origin xyz="0.130000 2.088607e-19 -0.003900"
            rpy="0 -0 -7.918786e-59" />
        <parent link="bodyv2" />
        <child link="coxav2-cp_r_2" />
        <axis xyz="0 0 1" />
        <limit effort="1" velocity="20" />
        <joint_properties friction="0.0" />
    </joint>

    <link name="coxav2-cp_r_3">
        <visual>
            <origin xyz="0.044924 3.257639e-16 0.015349"
                rpy="-2.220446e-16 4.157296e-27 8.040461e-17" />
            <geometry>
                <mesh filename="../meshes/coxav2-cp_r.obj" />
            </geometry>
            <material name="coxav2-cp_r_material">
                <color rgba="0.231372 0.380392 0.705882 1.0" />
            </material>
        </visual>
        <collision>
            <origin xyz="0.0155 0.0 0.0246" rpy="0.0 0.0 0.0"/>
            <geometry>  
                <box size="0.096265 0.0415 0.073"/>
            </geometry>
        </collision>
        <inertial>
            <origin xyz="0.030948 0.001527 0.025335"
                rpy="0 0 0" />
            <mass value="0.128842" />
            <inertia ixx="0.000110" ixy="-2.814921e-06"
                ixz="8.925042e-06" iyy="0.000160"
                iyz="1.713514e-06" izz="9.272238e-05" />
        </inertial>
    </link>

    <link name="femurv2-cp_r_3">
        <visual>
            <origin xyz="0.118313 -1.387778e-17 0.025049"
                rpy="-1.570796 2.844031e-16 -3.572700e-33" />
            <geometry>
                <mesh filename="../meshes/femurv2-cp_r.obj" />
            </geometry>
            <material name="femurv2-cp_r_material">
                <color
                    rgba="0.972549 0.529411 0.003921 1.0" />
            </material>
        </visual>
        <!-- <collision>
            <origin xyz="0.059156 0.0 0.0246" rpy="0.0 0.0 0.0"/>
            <geometry>  
                <box size="0.156314 0.0415 0.073"/>
            </geometry>
        </collision> -->
        <inertial>
            <origin xyz="0.060825 -1.513620e-09 0.026970"
                rpy="0 0 0" />
            <mass value="0.120701" />
            <inertia ixx="0.000123" ixy="-3.224433e-06"
                ixz="5.137608e-07" iyy="0.000324"
                iyz="-2.118779e-13" izz="0.000236" />
        </inertial>
    </link>

    <link name="tibiav2-cp_r_3">
        <visual>
            <origin xyz="0.221170 0.000104 0.025250"
                rpy="-1.570796 2.614011e-16 -5.203960e-33" />
            <geometry>
                <mesh filename="../meshes/tibiav2-cp_r.obj" />
            </geometry>
            <material name="tibiav2-cp_r_material">
                <color
                    rgba="0.980392 0.713725 0.003921 1.0" />
            </material>
        </visual>
        <!-- <collision>
            <origin xyz="0.013524 0.003617 0.02509" rpy="0.0 0.0 0.261341 "/>
            <geometry>  
                <box size="0.0655 0.0415 0.0417"/>
            </geometry>
        </collision> -->
        <inertial>
            <origin xyz="0.082592 0.012229 0.024032"
                rpy="0 0 0" />
            <mass value="0.168609" />
            <inertia ixx="6.244932e-05" ixy="-5.806436e-05"
                ixz="-1.625147e-05" iyy="0.000862"
                iyz="-2.394794e-06" izz="0.000872" />
        </inertial>
    </link>

    <joint name="FemurTibia3" type="revolute">
        <origin xyz="0.118313 1.734723e-18 1.387778e-17"
            rpy="-3.451266e-31 8.813414e-17 3.218650e-32" />
        <parent link="femurv2-cp_r_3" />
        <child link="tibiav2-cp_r_3" />
        <axis xyz="0 0 1" />
        <limit effort="1" velocity="20" />
        <joint_properties friction="0.0" />
    </joint>

    <joint name="CoxaFemur3" type="revolute">
        <origin xyz="0.044924 0.025050 0.015349"
            rpy="1.570796 4.157297e-27 5.562497e-17" />
        <parent link="coxav2-cp_r_3" />
        <child link="femurv2-cp_r_3" />
        <axis xyz="0 0 1" />
        <limit effort="1" velocity="20" />
        <joint_properties friction="0.0" />
    </joint>

    <joint name="BodyCoxa3" type="revolute">
        <origin xyz="0.098035 -0.150960 -0.004499"
            rpy="-1.972152e-31 -7.892112e-42 -0.994837" />
        <parent link="bodyv2" />
        <child link="coxav2-cp_r_3" />
        <axis xyz="0 0 1" />
        <limit effort="1" velocity="20" />
        <joint_properties friction="0.0" />
    </joint>

    <link name="coxav2-cp_l">
        <visual>
            <origin xyz="0.044924 -3.201838e-16 0.015349"
                rpy="-2.220446e-16 -4.157296e-27 -3.141592" />
            <geometry>
                <mesh filename="../meshes/coxav2-cp_l.obj" />
            </geometry>
            <material name="coxav2-cp_l_material">
                <color rgba="0.231372 0.380392 0.705882 1.0" />
            </material>
        </visual>
        <collision>
            <origin xyz="0.0155 0.0 0.0246" rpy="0.0 0.0 0.0"/>
            <geometry>  
                <box size="0.096265 0.0415 0.073"/>
            </geometry>
        </collision>
        <inertial>
            <origin xyz="0.030948 -0.001527 0.025335"
                rpy="0 0 0" />
            <mass value="0.128841" />
            <inertia ixx="0.000110" ixy="2.814856e-06"
                ixz="8.925372e-06" iyy="0.000160"
                iyz="-1.713214e-06" izz="9.272167e-05" />
        </inertial>
    </link>

    <link name="femurv2-cp_l">
        <visual>
            <origin xyz="0.118313 1.387778e-17 0.025049"
                rpy="-1.570796 -2.143492e-16 -3.141592" />
            <geometry>
                <mesh filename="../meshes/femurv2-cp_l.obj" />
            </geometry>
            <material name="femurv2-cp_l_material">
                <color
                    rgba="0.972549 0.529411 0.003921 1.0" />
            </material>
        </visual>
        <!-- <collision>
            <origin xyz="0.059156 0.0 0.0246" rpy="0.0 0.0 0.0"/>
            <geometry>  
                <box size="0.156314 0.0415 0.073"/>
            </geometry>
        </collision> -->
        <inertial>
            <origin xyz="0.060825 2.572845e-09 0.026970"
                rpy="0 0 0" />
            <mass value="0.120701" />
            <inertia ixx="0.000123" ixy="3.224424e-06"
                ixz="5.137535e-07" iyy="0.000324"
                iyz="3.363175e-12" izz="0.000236" />
        </inertial>
    </link>

    <link name="tibiav2-cp_l">
        <visual>
            <origin xyz="0.221170 -0.000104 0.025250"
                rpy="-1.570796 -2.976834e-16 3.141592" />
            <geometry>
                <mesh filename="../meshes/tibiav2-cp_l.obj" />
            </geometry>
            <material name="tibiav2-cp_l_material">
                <color
                    rgba="0.980392 0.713725 0.003921 1.0" />
            </material>
        </visual>
        <!-- <collision>
            <origin xyz="0.013524 0.003617 0.02509" rpy="0.0 0.0 0.261341 "/>
            <geometry>  
                <box size="0.0655 0.0415 0.0417"/>
            </geometry>
        </collision> -->
        <inertial>
            <origin xyz="0.082592 -0.012229 0.024032"
                rpy="0 0 0" />
            <mass value="0.168609" />
            <inertia ixx="6.244934e-05" ixy="5.806445e-05"
                ixz="-1.625180e-05" iyy="0.000862"
                iyz="2.394828e-06" izz="0.000872" />
        </inertial>
    </link>

    <joint name="FemurTibia4" type="revolute">
        <origin xyz="0.118313 -3.469446e-18 -4.510281e-17"
            rpy="0 5.277176e-17 -1.279796e-32" />
        <parent link="femurv2-cp_l" />
        <child link="tibiav2-cp_l" />
        <axis xyz="0 0 -1" />
        <limit effort="1" velocity="20" />
        <joint_properties friction="0.0" />
    </joint>

    <joint name="CoxaFemur4" type="revolute">
        <origin xyz="0.044924 -0.025050 0.015349"
            rpy="-1.570796 4.157294e-27 4.847357e-17" />
        <parent link="coxav2-cp_l" />
        <child link="femurv2-cp_l" />
        <axis xyz="0 0 -1" />
        <limit effort="1" velocity="20" />
        <joint_properties friction="0.0" />
    </joint>

    <joint name="BodyCoxa4" type="revolute">
        <origin xyz="-0.098035 -0.150960 -0.004499"
            rpy="-4.930380e-32 -7.892112e-42 -2.146754" />
        <parent link="bodyv2" />
        <child link="coxav2-cp_l" />
        <axis xyz="0 0 1" />
        <limit effort="1" velocity="20" />
        <joint_properties friction="0.0" />
    </joint>

    <link name="coxav2-cp_l_2">
        <visual>
            <origin xyz="0.044924 -3.202813e-16 0.015349"
                rpy="-2.220446e-16 -4.157296e-27 3.141592" />
            <geometry>
                <mesh filename="../meshes/coxav2-cp_l.obj" />
            </geometry>
            <material name="coxav2-cp_l_material">
                <color rgba="0.231372 0.380392 0.705882 1.0" />
            </material>
        </visual>
        <collision>
            <origin xyz="0.0155 0.0 0.0246" rpy="0.0 0.0 0.0"/>
            <geometry>  
                <box size="0.096265 0.0415 0.073"/>
            </geometry>
        </collision>
        <inertial>
            <origin xyz="0.030948 -0.001527 0.025335"
                rpy="0 0 0" />
            <mass value="0.128841" />
            <inertia ixx="0.000110" ixy="2.814856e-06"
                ixz="8.925372e-06" iyy="0.000160"
                iyz="-1.713214e-06" izz="9.272167e-05" />
        </inertial>
    </link>

    <link name="femurv2-cp_l_2">
        <visual>
            <origin xyz="0.118313 1.387778e-17 0.025049"
                rpy="-1.570796 -2.872393e-16 3.141592" />
            <geometry>
                <mesh filename="../meshes/femurv2-cp_l.obj" />
            </geometry>
            <material name="femurv2-cp_l_material">
                <color
                    rgba="0.972549 0.529411 0.003921 1.0" />
            </material>
        </visual>
        <!-- <collision>
            <origin xyz="0.059156 0.0 0.0246" rpy="0.0 0.0 0.0"/>
            <geometry>  
                <box size="0.156314 0.0415 0.073"/>
            </geometry>
        </collision> -->
        <inertial>
            <origin xyz="0.060825 2.572845e-09 0.026970"
                rpy="0 0 0" />
            <mass value="0.120701" />
            <inertia ixx="0.000123" ixy="3.224424e-06"
                ixz="5.137535e-07" iyy="0.000324"
                iyz="3.363175e-12" izz="0.000236" />
        </inertial>
    </link>

    <link name="tibiav2-cp_l_2">
        <visual>
            <origin xyz="0.221170 -0.000104 0.025250"
                rpy="-1.570796 -2.324140e-16 3.141592" />
            <geometry>
                <mesh filename="../meshes/tibiav2-cp_l.obj" />
            </geometry>
            <material name="tibiav2-cp_l_material">
                <color
                    rgba="0.980392 0.713725 0.003921 1.0" />
            </material>
        </visual>
        <!-- <collision>
            <origin xyz="0.013524 0.003617 0.02509" rpy="0.0 0.0 0.261341 "/>
            <geometry>  
                <box size="0.0655 0.0415 0.0417"/>
            </geometry>
        </collision> -->
        <inertial>
            <origin xyz="0.082592 -0.012229 0.024032"
                rpy="0 0 0" />
            <mass value="0.168609" />
            <inertia ixx="6.244934e-05" ixy="5.806445e-05"
                ixz="-1.625180e-05" iyy="0.000862"
                iyz="2.394828e-06" izz="0.000872" />
        </inertial>
    </link>

    <joint name="FemurTibia5" type="revolute">
        <origin xyz="0.118313 0 0" rpy="0 5.891547e-52 0" />
        <parent link="femurv2-cp_l_2" />
        <child link="tibiav2-cp_l_2" />
        <axis xyz="0 0 -1" />
        <limit effort="1" velocity="20" />
        <joint_properties friction="0.0" />
    </joint>

    <joint name="CoxaFemur5" type="revolute">
        <origin xyz="0.044924 -0.025050 0.015349"
            rpy="-1.570796 4.157296e-27 -1.183291e-30" />
        <parent link="coxav2-cp_l_2" />
        <child link="femurv2-cp_l_2" />
        <axis xyz="0 0 -1" />
        <limit effort="1" velocity="20" />
        <joint_properties friction="0.0" />
    </joint>

    <joint name="BodyCoxa5" type="revolute">
        <origin xyz="-0.130000 -1.598772e-15 -0.004500"
            rpy="0 -0 -3.141592" />
        <parent link="bodyv2" />
        <child link="coxav2-cp_l_2" />
        <axis xyz="0 0 1" />
        <limit effort="1" velocity="20" />
        <joint_properties friction="0.0" />
    </joint>

    <link name="coxav2-cp_l_3">
        <visual>
            <origin xyz="0.044924 -3.191324e-16 0.015349"
                rpy="-2.220446e-16 -4.157296e-27 -3.141592" />
            <geometry>
                <mesh filename="../meshes/coxav2-cp_l.obj" />
            </geometry>
            <material name="coxav2-cp_l_material">
                <color rgba="0.231372 0.380392 0.705882 1.0" />
            </material>
        </visual>
        <collision>
            <origin xyz="0.0155 0.0 0.0246" rpy="0.0 0.0 0.0"/>
            <geometry>  
                <box size="0.096265 0.0415 0.073"/>
            </geometry>
        </collision>
        <inertial>
            <origin xyz="0.030948 -0.001527 0.025335"
                rpy="0 0 0" />
            <mass value="0.128841" />
            <inertia ixx="0.000110" ixy="2.814856e-06"
                ixz="8.925372e-06" iyy="0.000160"
                iyz="-1.713214e-06" izz="9.272167e-05" />
        </inertial>
    </link>

    <link name="femurv2-cp_l_3">
        <visual>
            <origin xyz="0.118313 1.387778e-17 0.025049"
                rpy="-1.570796 -2.968333e-16 3.141592" />
            <geometry>
                <mesh filename="../meshes/femurv2-cp_l.obj" />
            </geometry>
            <material name="femurv2-cp_l_material">
                <color
                    rgba="0.972549 0.529411 0.003921 1.0" />
            </material>
        </visual>
        <!-- <collision>
            <origin xyz="0.059156 0.0 0.0246" rpy="0.0 0.0 0.0"/>
            <geometry>  
                <box size="0.156314 0.0415 0.073"/>
            </geometry>
        </collision> -->
        <inertial>
            <origin xyz="0.060825 2.572845e-09 0.026970"
                rpy="0 0 0" />
            <mass value="0.120701" />
            <inertia ixx="0.000123" ixy="3.224424e-06"
                ixz="5.137535e-07" iyy="0.000324"
                iyz="3.363175e-12" izz="0.000236" />
        </inertial>
    </link>

    <link name="tibiav2-cp_l_3">
        <visual>
            <origin xyz="0.221170 -0.000104 0.025250"
                rpy="-1.570796 -2.968333e-16 3.141592" />
            <geometry>
                <mesh filename="../meshes/tibiav2-cp_l.obj" />
            </geometry>
            <material name="tibiav2-cp_l_material">
                <color
                    rgba="0.980392 0.713725 0.003921 1.0" />
            </material>
        </visual>
        <!-- <collision>
            <origin xyz="0.013524 0.003617 0.02509" rpy="0.0 0.0 0.261341 "/>
            <geometry>  
                <box size="0.0655 0.0415 0.0417"/>
            </geometry>
        </collision> -->
        <inertial>
            <origin xyz="0.082592 -0.012229 0.024032"
                rpy="0 0 0" />
            <mass value="0.168609" />
            <inertia ixx="6.244934e-05" ixy="5.806445e-05"
                ixz="-1.625180e-05" iyy="0.000862"
                iyz="2.394828e-06" izz="0.000872" />
        </inertial>
    </link>

    <joint name="FemurTibia6" type="revolute">
        <origin xyz="0.118313 -3.469446e-18 -4.163336e-17"
            rpy="0 1.432164e-17 -8.337021e-33" />
        <parent link="femurv2-cp_l_3" />
        <child link="tibiav2-cp_l_3" />
        <axis xyz="0 0 -1" />
        <limit effort="1" velocity="20" />
        <joint_properties friction="0.0" />
    </joint>

    <joint name="CoxaFemur6" type="revolute">
        <origin xyz="0.044924 -0.025050 0.015350"
            rpy="-1.570796 4.157297e-27 5.367175e-18" />
        <parent link="coxav2-cp_l_3" />
        <child link="femurv2-cp_l_3" />
        <axis xyz="0 0 -1" />
        <limit effort="1" velocity="20" />
        <joint_properties friction="0.0" />
    </joint>

    <joint name="BodyCoxa6" type="revolute">
        <origin xyz="-0.098035 0.150960 -0.004499"
            rpy="0 -1.232595e-32 2.146754" />
        <parent link="bodyv2" />
        <child link="coxav2-cp_l_3" />
        <axis xyz="0 0 1" />
        <limit effort="1" velocity="20" />
        <joint_properties friction="0.0" />
    </joint>

    <link name="Foot1">
        <visual name="">
            <origin xyz="0.215305 0.0025 0.025250" rpy="0.0 0.0 0.0"/>
            <geometry>
                <sphere radius="0.006635"/>
            </geometry>
        </visual>
        <collision>
            <origin xyz="0.215305 0.0025 0.025250" rpy="0.0 0.0 0.0"/>
            <geometry>
                <sphere radius="0.006635"/>
            </geometry>
        </collision>
    </link>

    <joint name="Foot1" type="fixed">
        <origin xyz="0.0 0.0 0.0" rpy="0.0 0.0 0.0"/>
        <parent link="tibiav2-cp_r"/>
        <child link="Foot1"/>
        <axis xyz="0.0 0.0 0.0"/>
    </joint>

    <link name="Foot2">
        <visual name="">
            <origin xyz="0.215305 0.0025 0.025250" rpy="0.0 0.0 0.0"/>
            <geometry>
                <sphere radius="0.006635"/>
            </geometry>
        </visual>
        <collision>
            <origin xyz="0.215305 0.0025 0.025250" rpy="0.0 0.0 0.0"/>
            <geometry>
                <sphere radius="0.006635"/>
            </geometry>
        </collision>
    </link>

    <joint name="Foot2" type="fixed">
        <origin xyz="0.0 0.0 0.0" rpy="0.0 0.0 0.0"/>
        <parent link="tibiav2-cp_r_2"/>
        <child link="Foot2"/>
        <axis xyz="0.0 0.0 0.0"/>
    </joint>

    <link name="Foot3">
        <visual name="">
            <origin xyz="0.215305 0.0025 0.025250" rpy="0.0 0.0 0.0"/>
            <geometry>
                <sphere radius="0.006635"/>
            </geometry>
        </visual>
        <collision>
            <origin xyz="0.215305 0.0025 0.025250" rpy="0.0 0.0 0.0"/>
            <geometry>
                <sphere radius="0.006635"/>
            </geometry>
        </collision>
    </link>

    <joint name="Foot3" type="fixed">
        <origin xyz="0.0 0.0 0.0" rpy="0.0 0.0 0.0"/>
        <parent link="tibiav2-cp_r_3"/>
        <child link="Foot3"/>
        <axis xyz="0.0 0.0 0.0"/>
    </joint>

    <link name="Foot4">
        <visual name="">
            <origin xyz="0.215305 -0.0025 0.025250" rpy="0.0 0.0 0.0"/>
            <geometry>
                <sphere radius="0.006635"/>
            </geometry>
        </visual>
        <collision>
            <origin xyz="0.215305 -0.0025 0.025250" rpy="0.0 0.0 0.0"/>
            <geometry>
                <sphere radius="0.006635"/>
            </geometry>
        </collision>
    </link>

    <joint name="Foot4" type="fixed">
        <origin xyz="0.0 0.0 0.0" rpy="0.0 0.0 0.0"/>
        <parent link="tibiav2-cp_l"/>
        <child link="Foot4"/>
        <axis xyz="0.0 0.0 0.0"/>
    </joint>

    <link name="Foot5">
        <visual name="">
            <origin xyz="0.215305 -0.0025 0.025250" rpy="0.0 0.0 0.0"/>
            <geometry>
                <sphere radius="0.006635"/>
            </geometry>
        </visual>
        <collision>
            <origin xyz="0.215305 -0.0025 0.025250" rpy="0.0 0.0 0.0"/>
            <geometry>
                <sphere radius="0.006635"/>
            </geometry>
        </collision>
    </link>

    <joint name="Foot5" type="fixed">
        <origin xyz="0.0 0.0 0.0" rpy="0.0 0.0 0.0"/>
        <parent link="tibiav2-cp_l_2"/>
        <child link="Foot5"/>
        <axis xyz="0.0 0.0 0.0"/>
    </joint>

    <link name="Foot6">
        <visual name="">
            <origin xyz="0.215305 -0.0025 0.025250" rpy="0.0 0.0 0.0"/>
            <geometry>
                <sphere radius="0.006635"/>
            </geometry>
        </visual>
        <collision>
            <origin xyz="0.215305 -0.0025 0.025250" rpy="0.0 0.0 0.0"/>
            <geometry>
                <sphere radius="0.006635"/>
            </geometry>
        </collision>
    </link>

    <joint name="Foot6" type="fixed">
        <origin xyz="0.0 0.0 0.0" rpy="0.0 0.0 0.0"/>
        <parent link="tibiav2-cp_l_3"/>
        <child link="Foot6"/>
        <axis xyz="0.0 0.0 0.0"/>
    </joint>
</robot>